Traceback (most recent call last):
  File "/usr/local/lib/python3.9/site-packages/jupyter_cache/executors/utils.py", line 51, in single_nb_execution
    executenb(
  File "/usr/local/lib/python3.9/site-packages/nbclient/client.py", line 1112, in execute
    return NotebookClient(nb=nb, resources=resources, km=km, **kwargs).execute()
  File "/usr/local/lib/python3.9/site-packages/nbclient/util.py", line 74, in wrapped
    return just_run(coro(*args, **kwargs))
  File "/usr/local/lib/python3.9/site-packages/nbclient/util.py", line 53, in just_run
    return loop.run_until_complete(coro)
  File "/usr/lib64/python3.9/asyncio/base_events.py", line 642, in run_until_complete
    return future.result()
  File "/usr/local/lib/python3.9/site-packages/nbclient/client.py", line 553, in async_execute
    await self.async_execute_cell(
  File "/usr/local/lib/python3.9/site-packages/nbclient/client.py", line 857, in async_execute_cell
    self._check_raise_for_error(cell, exec_reply)
  File "/usr/local/lib/python3.9/site-packages/nbclient/client.py", line 760, in _check_raise_for_error
    raise CellExecutionError.from_cell_and_msg(cell, exec_reply_content)
nbclient.exceptions.CellExecutionError: An error occurred while executing the following cell:
------------------
#@title
# General imports
import json
import rdflib
import requests
from rdflib import Graph, plugin
from rdflib.serializer import Serializer
from bs4 import BeautifulSoup
import urllib.request

from rdflib.extras.external_graph_libs import rdflib_to_networkx_multidigraph
from rdflib.extras.external_graph_libs import rdflib_to_networkx_graph
import networkx as nx
from networkx import Graph as NXGraph
import matplotlib.pyplot as plt
import statistics
import collections

# for JSON-LD work
from pyld import jsonld

# For SHACL
from pyshacl import validate

# concept net
import graphviz
from conceptnet5.uri import join_uri, split_uri
API_ROOT = 'http://api.conceptnet.io'


------------------

[0;31m---------------------------------------------------------------------------[0m
[0;31mModuleNotFoundError[0m                       Traceback (most recent call last)
[0;32m<ipython-input-2-05965b657363>[0m in [0;36m<module>[0;34m[0m
[1;32m     25[0m [0;31m# concept net[0m[0;34m[0m[0;34m[0m[0;34m[0m[0m
[1;32m     26[0m [0;32mimport[0m [0mgraphviz[0m[0;34m[0m[0;34m[0m[0m
[0;32m---> 27[0;31m [0;32mfrom[0m [0mconceptnet5[0m[0;34m.[0m[0muri[0m [0;32mimport[0m [0mjoin_uri[0m[0;34m,[0m [0msplit_uri[0m[0;34m[0m[0;34m[0m[0m
[0m[1;32m     28[0m [0mAPI_ROOT[0m [0;34m=[0m [0;34m'http://api.conceptnet.io'[0m[0;34m[0m[0;34m[0m[0m
[1;32m     29[0m [0;34m[0m[0m

[0;31mModuleNotFoundError[0m: No module named 'conceptnet5'
ModuleNotFoundError: No module named 'conceptnet5'

